Workbook

Sheet STOCK NUEVOS
A1: ALIANZA | B1: NEMOTECNICO | C1: NOMBRE PROYECTO | D1: TIPO ENTREGA | E1: PERIODO ENTREGA | F1: DIRECCION | G1: COMUNA | H1: ESTADO STOCK | I1: TIPO UNIDAD | J1: PROGRAMA | K1: PISO PRODUCTO | L1: NUMERO UNIDAD | M1: ORIENTACION | N1: DORMITORIOS | O1: BAÑOS | P1: PRECIO LISTA | Q1: SUPERFICIE TERRENO | R1: SUPERFICIE UTIL | S1: SUPERFICIE TERRAZA | T1: SUPERFICIE TOTAL | U1: BIENES CONJUNTOS
A2: INGEVEC | B2: TOC | C2: TOCORNAL | D2: Entrega Inmediata | E2: Inmediata | F2: Manuel Antonio Tocornal 670 | G2: Santiago | H2: Disponible | I2: Departamento | J2: 2D1B | K2: 2 | L2: 213 | M2: ORIENTE | N2: 2 | O2: 1 | P2: 3890 | R2: 43,35 | S2: 5,03 | T2: 48.38
A3: INGEVEC | B3: TOC | C3: TOCORNAL | D3: Entrega Inmediata | E3: Inmediata | F3: Manuel Antonio Tocornal 670 | G3: Santiago | H3: Disponible | I3: Departamento | J3: 1D1B | K3: 2 | L3: 219 | M3: PONIENTE | N3: 1 | O3: 1 | P3: 3237 | R3: 33,59 | S3: 0 | T3: 33.59
A4: INGEVEC | B4: TOC | C4: TOCORNAL | D4: Entrega Inmediata | E4: Inmediata | F4: Manuel Antonio Tocornal 670 | G4: Santiago | H4: Disponible | I4: Departamento | J4: 2D2B | K4: 3 | L4: 305 | M4: SUR | N4: 2 | O4: 2 | P4: 3901 | R4: 43,83 | S4: 4,19 | T4: 48.02
A5: INGEVEC | B5: TOC | C5: TOCORNAL | D5: Entrega Inmediata | E5: Inmediata | F5: Manuel Antonio Tocornal 670 | G5: Santiago | H5: Disponible | I5: Departamento | J5: 2D1B | K5: 3 | L5: 313 | M5: ORIENTE | N5: 2 | O5: 1 | P5: 3930 | R5: 43,35 | S5: 5,03 | T5: 48.38
A6: INGEVEC | B6: TOC | C6: TOCORNAL | D6: Entrega Inmediata | E6: Inmediata | F6: Manuel Antonio Tocornal 670 | G6: Santiago | H6: Disponible | I6: Departamento | J6: 1D1B | K6: 3 | L6: 315 | M6: PONIENTE | N6: 1 | O6: 1 | P6: 3216 | R6: 32,35 | S6: 4,22 | T6: 36.57
A7: INGEVEC | B7: TOC | C7: TOCORNAL | D7: Entrega Inmediata | E7: Inmediata | F7: Manuel Antonio Tocornal 670 | G7: Santiago | H7: Disponible | I7: Departamento | J7: 2D2B | K7: 4 | L7: 405 | M7: SUR | N7: 2 | O7: 2 | P7: 3915 | R7: 43,83 | S7: 4,19 | T7: 48.02
A8: INGEVEC | B8: TOC | C8: TOCORNAL | D8: Entrega Inmediata | E8: Inmediata | F8: Manuel Antonio Tocornal 670 | G8: Santiago | H8: Disponible | I8: Departamento | J8: 2D2B | K8: 4 | L8: 417 | M8: PONIENTE | N8: 2 | O8: 2 | P8: 4011 | R8: 45,79 | S8: 4,2 | T8: 49.99
A9: INGEVEC | B9: TOC | C9: TOCORNAL | D9: Entrega Inmediata | E9: Inmediata | F9: Manuel Antonio Tocornal 670 | G9: Santiago | H9: Disponible | I9: Departamento | J9: 1D1B | K9: 5 | L9: 512 | M9: ORIENTE | N9: 1 | O9: 1 | P9: 3312 | R9: 32,35 | S9: 4,15 | T9: 36.5
A10: INGEVEC | B10: TOC | C10: TOCORNAL | D10: Entrega Inmediata | E10: Inmediata | F10: Manuel Antonio Tocornal 670 | G10: Santiago | H10: Disponible | I10: Departamento | J10: 2D1B | K10: 5 | L10: 513 | M10: ORIENTE | N10: 2 | O10: 1 | P10: 3955 | R10: 43,35 | S10: 5,03 | T10: 48.38
A11: INGEVEC | B11: TOC | C11: TOCORNAL | D11: Entrega Inmediata | E11: Inmediata | F11: Manuel Antonio Tocornal 670 | G11: Santiago | H11: Disponible | I11: Departamento | J11: 2D2B | K11: 5 | L11: 517 | M11: PONIENTE | N11: 2 | O11: 2 | P11: 4024 | R11: 45,79 | S11: 4,2 | T11: 49.99
A12: INGEVEC | B12: TOC | C12: TOCORNAL | D12: Entrega Inmediata | E12: Inmediata | F12: Manuel Antonio Tocornal 670 | G12: Santiago | H12: Disponible | I12: Departamento | J12: 1D1B | K12: 5 | L12: 519 | M12: PONIENTE | N12: 1 | O12: 1 | P12: 3236 | R12: 32,35 | S12: 4,22 | T12: 36.57
A13: INGEVEC | B13: TOC | C13: TOCORNAL | D13: Entrega Inmediata | E13: Inmediata | F13: Manuel Antonio Tocornal 670 | G13: Santiago | H13: Disponible | I13: Departamento | J13: 2D2B | K13: 6 | L13: 617 | M13: PONIENTE | N13: 2 | O13: 2 | P13: 4036 | R13: 45,79 | S13: 4,2 | T13: 49.99
... A25: INGEVEC | B25: TOC | C25: TOCORNAL | D25: Entrega Inmediata | E25: Inmediata | F25: Manuel Antonio Tocornal 670 | G25: Santiago | H25: Disponible | I25: Departamento | J25: 1D1B | K25: 9 | L25: 918 | M25: PONIENTE | N25: 1 | O25: 1 | P25: 3290 | R25: 32,35 | S25: 4,31 | T25: 36.66
A26: INGEVEC | B26: TOC | C26: TOCORNAL | D26: Entrega Inmediata | E26: Inmediata | F26: Manuel Antonio Tocornal 670 | G26: Santiago | H26: Disponible | I26: Estacionamiento | J26: Estacionamiento | K26: 0 | L26: 1 | P26: 345 | T26: 0
A27: INGEVEC | B27: TOC | C27: TOCORNAL | D27: Entrega Inmediata | E27: Inmediata | F27: Manuel Antonio Tocornal 670 | G27: Santiago | H27: Disponible | I27: Estacionamiento | J27: Estacionamiento | K27: 0 | L27: 2 | P27: 345 | T27: 0
A28: INGEVEC | B28: TOC | C28: TOCORNAL | D28: Entrega Inmediata | E28: Inmediata | F28: Manuel Antonio Tocornal 670 | G28: Santiago | H28: Disponible | I28: Estacionamiento | J28: Estacionamiento | K28: 0 | L28: 3 | P28: 459 | T28: 0
A29: INGEVEC | B29: TOC | C29: TOCORNAL | D29: Entrega Inmediata | E29: Inmediata | F29: Manuel Antonio Tocornal 670 | G29: Santiago | H29: Disponible | I29: Estacionamiento | J29: Estacionamiento | K29: 0 | L29: 4 | P29: 345 | T29: 0
A30: INGEVEC | B30: TOC | C30: TOCORNAL | D30: Entrega Inmediata | E30: Inmediata | F30: Manuel Antonio Tocornal 670 | G30: Santiago | H30: Disponible | I30: Estacionamiento | J30: Estacionamiento | K30: 0 | L30: 6 | P30: 345 | T30: 0
A31: INGEVEC | B31: TOC | C31: TOCORNAL | D31: Entrega Inmediata | E31: Inmediata | F31: Manuel Antonio Tocornal 670 | G31: Santiago | H31: Disponible | I31: Estacionamiento | J31: Estacionamiento | K31: 0 | L31: 8 | P31: 345 | T31: 0
A32: INGEVEC | B32: TOC | C32: TOCORNAL | D32: Entrega Inmediata | E32: Inmediata | F32: Manuel Antonio Tocornal 670 | G32: Santiago | H32: Disponible | I32: Estacionamiento | J32: Estacionamiento | K32: 0 | L32: 9 | P32: 338 | T32: 0
A33: INGEVEC | B33: TOC | C33: TOCORNAL | D33: Entrega Inmediata | E33: Inmediata | F33: Manuel Antonio Tocornal 670 | G33: Santiago | H33: Disponible | I33: Estacionamiento | J33: Estacionamiento | K33: 0 | L33: 11 | P33: 338 | T33: 0
A34: INGEVEC | B34: TOC | C34: TOCORNAL | D34: Entrega Inmediata | E34: Inmediata | F34: Manuel Antonio Tocornal 670 | G34: Santiago | H34: Disponible | I34: Estacionamiento | J34: Estacionamiento | K34: 0 | L34: 12 | P34: 322 | T34: 0
A35: INGEVEC | B35: TOC | C35: TOCORNAL | D35: Entrega Inmediata | E35: Inmediata | F35: Manuel Antonio Tocornal 670 | G35: Santiago | H35: Disponible | I35: Estacionamiento | J35: Estacionamiento | K35: 0 | L35: 15 | P35: 315 | T35: 0
A36: INGEVEC | B36: TOC | C36: TOCORNAL | D36: Entrega Inmediata | E36: Inmediata | F36: Manuel Antonio Tocornal 670 | G36: Santiago | H36: Disponible | I36: Estacionamiento | J36: Estacionamiento | K36: 0 | L36: 16 | P36: 322 | T36: 0
A37: INGEVEC | B37: TOC | C37: TOCORNAL | D37: Entrega Inmediata | E37: Inmediata | F37: Manuel Antonio Tocornal 670 | G37: Santiago | H37: Disponible | I37: Estacionamiento | J37: Estacionamiento | K37: 0 | L37: 23 | P37: 429 | T37: 0
... A73: INGEVEC | B73: TOC | C73: TOCORNAL | D73: Entrega Inmediata | E73: Inmediata | F73: Manuel Antonio Tocornal 670 | G73: Santiago | H73: Disponible | I73: Estacionamiento | J73: Estacionamiento | K73: 0 | L73: 89 | P73: 306 | T73: 0
A74: MAESTRA | B74: ALTO BUZETA (MT) | C74: ALTO BUZETA (MT) | D74: Entrega Inmediata | E74: Inmediata | F74: Av. Cinco 2951 | G74: Cerrillos | H74: Disponible | I74: Departamento | J74: 1D1BSg | K74: 3 | L74: 317 | M74: SUR PONIENTE | N74: 1 | O74: 1 | P74: 2456 | R74: 29,76 | S74: 0 | T74: 29.76
A75: MAESTRA | B75: ALTO BUZETA (MT) | C75: ALTO BUZETA (MT) | D75: Entrega Inmediata | E75: Inmediata | F75: Av. Cinco 2951 | G75: Cerrillos | H75: Disponible | I75: Departamento | J75: 1D1BSg | K75: 4 | L75: 417 | M75: SUR PONIENTE | N75: 1 | O75: 1 | P75: 2468 | R75: 29,76 | S75: 0 | T75: 29.76
A76: MAESTRA | B76: ALTO BUZETA (MT) | C76: ALTO BUZETA (MT) | D76: Entrega Inmediata | E76: Inmediata | F76: Av. Cinco 2951 | G76: Cerrillos | H76: En Recolocación | I76: Departamento | J76: 2D1B | K76: 8 | L76: 807 | M76: NOR PONIENTE | N76: 2 | O76: 1 | P76: 2770 | R76: 36,14 | S76: 2,05 | T76: 38.19
A77: MAESTRA | B77: ALTO BUZETA (MT) | C77: ALTO BUZETA (MT) | D77: Entrega Inmediata | E77: Inmediata | F77: Av. Cinco 2951 | G77: Cerrillos | H77: Disponible | I77: Departamento | J77: 2Dg1B | K77: 1 | L77: 103 | M77: SUR ORIENTE | N77: 2 | O77: 1 | P77: 2932 | R77: 45,61 | S77: 2,66 | T77: 48.27 | U77: B - 64
A78: MAESTRA | B78: ALTO BUZETA (MT) | C78: ALTO BUZETA (MT) | D78: Entrega Inmediata | E78: Inmediata | F78: Av. Cinco 2951 | G78: Cerrillos | H78: Disponible | I78: Departamento | J78: 2Dg1B | K78: 4 | L78: 405 | M78: NOR PONIENTE | N78: 2 | O78: 1 | P78: 3041 | R78: 43,1 | S78: 2,24 | T78: 45.34
A79: MAESTRA | B79: ALTO BUZETA (MT) | C79: ALTO BUZETA (MT) | D79: Entrega Inmediata | E79: Inmediata | F79: Av. Cinco 2951 | G79: Cerrillos | H79: Disponible | I79: Departamento | J79: 2Dg1B | K79: 4 | L79: 414 | M79: NOR ORIENTE | N79: 2 | O79: 1 | P79: 3065 | R79: 43,1 | S79: 2,24 | T79: 45.34
A80: MAESTRA | B80: ALTO BUZETA (MT) | C80: ALTO BUZETA (MT) | D80: Entrega Inmediata | E80: Inmediata | F80: Av. Cinco 2951 | G80: Cerrillos | H80: Disponible | I80: Departamento | J80: 2Dg1B | K80: 5 | L80: 509 | M80: NOR PONIENTE | N80: 2 | O80: 1 | P80: 3053 | R80: 43,49 | S80: 2,24 | T80: 45.73
A81: MAESTRA | B81: ALTO BUZETA (MT) | C81: ALTO BUZETA (MT) | D81: Entrega Inmediata | E81: Inmediata | F81: Av. Cinco 2951 | G81: Cerrillos | H81: Disponible | I81: Departamento | J81: 2Dg1B | K81: 5 | L81: 513 | M81: NOR ORIENTE | N81: 2 | O81: 1 | P81: 3078 | R81: 46,44 | S81: 2,77 | T81: 49.21
A82: MAESTRA | B82: ALTO BUZETA (MT) | C82: ALTO BUZETA (MT) | D82: Entrega Inmediata | E82: Inmediata | F82: Av. Cinco 2951 | G82: Cerrillos | H82: Disponible | I82: Departamento | J82: 2Dg1B | K82: 6 | L82: 609 | M82: NOR PONIENTE | N82: 2 | O82: 1 | P82: 3065 | R82: 43,49 | S82: 2,24 | T82: 45.73
A83: MAESTRA | B83: ALTO BUZETA (MT) | C83: ALTO BUZETA (MT) | D83: Entrega Inmediata | E83: Inmediata | F83: Av. Cinco 2951 | G83: Cerrillos | H83: Disponible | I83: Departamento | J83: 2Dg1B | K83: 6 | L83: 613 | M83: NOR ORIENTE | N83: 2 | O83: 1 | P83: 3090 | R83: 46,44 | S83: 2,77 | T83: 49.21
A84: MAESTRA | B84: ALTO BUZETA (MT) | C84: ALTO BUZETA (MT) | D84: Entrega Inmediata | E84: Inmediata | F84: Av. Cinco 2951 | G84: Cerrillos | H84: Disponible | I84: Departamento | J84: 2Dg1B | K84: 7 | L84: 705 | M84: NOR PONIENTE | N84: 2 | O84: 1 | P84: 3078 | R84: 43,61 | S84: 2,24 | T84: 45.85 | U84: B - 69
A85: MAESTRA | B85: ALTO BUZETA (MT) | C85: ALTO BUZETA (MT) | D85: Entrega Inmediata | E85: Inmediata | F85: Av. Cinco 2951 | G85: Cerrillos | H85: Disponible | I85: Departamento | J85: 2Dg1B | K85: 7 | L85: 709 | M85: NOR PONIENTE | N85: 2 | O85: 1 | P85: 3078 | R85: 43,49 | S85: 2,24 | T85: 45.73
A86: MAESTRA | B86: ALTO BUZETA (MT) | C86: ALTO BUZETA (MT) | D86: Entrega Inmediata | E86: Inmediata | F86: Av. Cinco 2951 | G86: Cerrillos | H86: Disponible | I86: Departamento | J86: 2Dg1B | K86: 7 | L86: 713 | M86: NOR ORIENTE | N86: 2 | O86: 1 | P86: 3102 | R86: 46,44 | S86: 2,77 | T86: 49.21
...

Sheet CONDICIONES_COMERCIALES
A1: ALIANZA | B1: NEMOTECNICO | C1: NOMBRE PROYECTO | D1: ESTADO PROYECTO | E1: TIPO UNIDAD | F1: PROGRAMA | G1: RESERVA | H1: DESCUENTO | I1: BONO PIE | J1: CUOTAS PIE | K1: PIE PERÍODO CONSTRUCCIÓN | L1: CUOTÓN | M1: PIE CRÉDITO DIRECTO
A2: INGEVEC | B2: ABD | C2: ABDÓN CIFUENTES | D2: ACTIVO | E2: Bodega | F2: Bodega | G2: 100000 | H2: 0 | I2: 0 | J2: 1 | K2: 0 | L2: 0 | M2: 0
A3: INGEVEC | B3: ABD | C3: ABDÓN CIFUENTES | D3: ACTIVO | E3: Departamento | F3: 1-1/2D2B | G3: 100000 | H3: 0 | I3: 0.09 | J3: 27 | K3: 0.06 | L3: 0 | M3: 0.05
A4: INGEVEC | B4: ABD | C4: ABDÓN CIFUENTES | D4: ACTIVO | E4: Departamento | F4: 1D1B | G4: 100000 | H4: 0 | I4: 0.09 | J4: 27 | K4: 0.06 | L4: 0 | M4: 0.05
A5: INGEVEC | B5: ABD | C5: ABDÓN CIFUENTES | D5: ACTIVO | E5: Departamento | F5: 2D2B | G5: 100000 | H5: 0 | I5: 0.09 | J5: 27 | K5: 0.06 | L5: 0 | M5: 0.05
A6: INGEVEC | B6: ABD | C6: ABDÓN CIFUENTES | D6: ACTIVO | E6: Estacionamiento | F6: Estacionamiento | G6: 100000 | H6: 0 | I6: 0 | J6: 1 | K6: 0 | L6: 0 | M6: 0
A7: INGEVEC | B7: ALE | C7: LOS ALERCES | D7: ACTIVO | E7: Bodega | F7: Bodega | G7: 100000 | H7: 0 | I7: 0 | J7: 1 | K7: 0 | L7: 0 | M7: 0
A8: INGEVEC | B8: ALE | C8: LOS ALERCES | D8: ACTIVO | E8: Departamento | F8: 1D1B | G8: 100000 | H8: 0 | I8: 0.1 | J8: 1 | K8: 0.03 | L8: 0.02 | M8: 0.05
A9: INGEVEC | B9: ALE | C9: LOS ALERCES | D9: ACTIVO | E9: Departamento | F9: 2D2B | G9: 100000 | H9: 0 | I9: 0.1 | J9: 1 | K9: 0.03 | L9: 0.02 | M9: 0.05
A10: INGEVEC | B10: ALE | C10: LOS ALERCES | D10: ACTIVO | E10: Estacionamiento | F10: Estacionamiento | G10: 100000 | H10: 0 | I10: 0 | J10: 1 | K10: 0 | L10: 0 | M10: 0
A11: INGEVEC | B11: ARO | C11: EL AROMO | D11: ACTIVO | E11: Bodega | F11: Bodega | G11: 100000 | H11: 0 | I11: 0 | J11: 1 | K11: 0 | L11: 0 | M11: 0
A12: INGEVEC | B12: ARO | C12: EL AROMO | D12: ACTIVO | E12: Departamento | F12: 1D1B | G12: 100000 | H12: 0.02 | I12: 0.11 | J12: 20 | K12: 0.04 | L12: 0 | M12: 0.05
A13: INGEVEC | B13: ARO | C13: EL AROMO | D13: ACTIVO | E13: Departamento | F13: 2D1B(3) | G13: 100000 | H13: 0.02 | I13: 0.11 | J13: 20 | K13: 0.04 | L13: 0 | M13: 0.05
... A310: URMENETA | B310: Sueña Toesca | C310: Sueña Toesca | D310: ACTIVO | E310: Departamento | F310: 2D/2B 1S KI (G) | G310: 226000 | H310: 0.2 | I310: 0 | J310: 18 | K310: 0 | L310: 0 | M310: 0

Sheet PROYECTOS
A1: ALIANZA | B1: NOMBRE PROYECTO | C1: NEMOTECNICO | D1: COMUNA | E1: DIRECCION | F1: TIPO ENTREGA | G1: PERIODO ENTREGA
A2: INGEVEC | B2: ABDÓN CIFUENTES | C2: ABD | D2: Santiago | E2: Abdón Cifuentes 90 | F2: Entrega Futura | G2: 1er semestre 2028
A3: INGEVEC | B3: BELLAVISTA | C3: BEL | D3: La Florida | E3: Bellavista 7150 | F3: Entrega Inmediata | G3: Inmediata
A4: INGEVEC | B4: BRASIL | C4: BRA | D4: Santiago | E4: Brasil 1290 | F4: Entrega Futura | G4: 1er semestre 2029
A5: INGEVEC | B5: CENTENARIO I | C5: FRK | D5: Santiago | E5: San Diego 2381 | F5: Entrega Inmediata | G5: Inmediata
A6: INGEVEC | B6: CORONEL GODOY | C6: GOD | D6: Estacion Central | E6: Ecuador 420 | F6: Entrega Futura | G6: 2do semestre 2028
A7: INGEVEC | B7: CURAUMA | C7: CUR | D7: Valparaiso | E7: Sin Informacion | F7: Entrega Futura | G7: Sin Informacion
A8: INGEVEC | B8: DIAGONAL PARAGUAY | C8: DP | D8: Santiago | E8: Diagonal Paraguay 240 | F8: Entrega Futura | G8: 2do semestre 2027
A9: INGEVEC | B9: DON IGNACIO | C9: DOM | D9: Santiago | E9: Avenida Manuel Rodríguez 701 | F9: Entrega Futura | G9: 2do semestre 2028
A10: INGEVEC | B10: EL AROMO | C10: ARO | D10: La Florida | E10: El Aromo 6725 | F10: Entrega Futura | G10: 2do semestre 2027
A11: INGEVEC | B11: FROILAN ROA | C11: ROA | D11: La Florida | E11: Froilán Roa 5746 | F11: Entrega Inmediata | G11: Inmediata
A12: INGEVEC | B12: LOS ALERCES | C12: ALE | D12: Ñuñoa | E12: Los Alerces 3254 | F12: Entrega Inmediata | G12: Inmediata
... A100: URMENETA | B100: ZAÑARTU 1908 | C100: ZAÑARTU 1908 | D100: Ñuñoa | E100: Zañartu 1908 | F100: Entrega Futura | G100: 1er Semestre 2028

Sheet UF
A1: MONEDA | B1: PERIODO | C1: FECHA | D1: VALOR | E1: VARIACION_DIARIA
A2: UF | B2: 1977-08 | C2: 28338 | D2: 389.1 | E2: 0
A3: UF | B3: 1977-08 | C3: 28339 | D3: 389.51 | E3: 0.41
A4: UF | B4: 1977-08 | C4: 28340 | D4: 389.91 | E4: 0.4
A5: UF | B5: 1977-08 | C5: 28341 | D5: 390.32 | E5: 0.41
A6: UF | B6: 1977-08 | C6: 28342 | D6: 390.73 | E6: 0.41
A7: UF | B7: 1977-08 | C7: 28343 | D7: 391.14 | E7: 0.41
A8: UF | B8: 1977-08 | C8: 28344 | D8: 391.55 | E8: 0.41
A9: UF | B9: 1977-08 | C9: 28345 | D9: 391.96 | E9: 0.41
A10: UF | B10: 1977-08 | C10: 28346 | D10: 392.37 | E10: 0.41
A11: UF | B11: 1977-08 | C11: 28347 | D11: 392.85 | E11: 0.48
A12: UF | B12: 1977-08 | C12: 28348 | D12: 393.34 | E12: 0.49
A13: UF | B13: 1977-08 | C13: 28349 | D13: 393.83 | E13: 0.49
... A17785: UF | B17785: 2026-04 | C17785: 46121 | D17785: 39841.72 | E17785: 0

Sheet COTIZADOR
B2: DIGITAR MANUALMENTE
B3: SELECCIONAR UNA OPCIÓN
B7: Cotización
B9: Nombre Broker
B10: Nombre Cliente | E10: E-mail
B11: Rut | E11: Celular
B13: Datos del proyecto
B16: Comuna | C16: La Florida | E16: Entrega Aprox. | F16: Entrega Inmediata
B18: Inmobiliaria | C18: MAESTRA | E18: Proyecto | F18: PLAZA CERVANTES I
B21: Características de la propiedad
B23: Nº Unidad | C23: 113 | D23: Piso | E23: =_xlfn.XLOOKUP($C$23,'aux2'!O:O,'aux2'!N:N) | F23: Orientación | G23: =_xlfn.XLOOKUP($C$23,'aux2'!$O:$O,'aux2'!$P:$P)
B24: Tipología | C24: =_xlfn.XLOOKUP($C$23,'aux2'!$O:$O,'aux2'!$M:$M) | D24: Dormitorios | E24: =_xlfn.XLOOKUP($C$23,'aux2'!$O:$O,'aux2'!$Q:$Q) | F24: Baños | G24: =_xlfn.XLOOKUP($C$23,'aux2'!$O:$O,'aux2'!$R:$R)
B25: Sup. Útil | C25: =_xlfn.XLOOKUP($C$23,'aux2'!$O:$O,'aux2'!$U:$U) | D25: Sup. Terraza | E25: =_xlfn.XLOOKUP($C$23,'aux2'!$O:$O,'aux2'!$V:$V) | F25: Sup. Total | G25: =_xlfn.XLOOKUP($C$23,'aux2'!$O:$O,'aux2'!$W:$W)
B26: Valor UF | C26: =VLOOKUP(TODAY(),[1]UF!$C:$D,2,0)
B28: Valores
E30: UF | F30: % | G30: $
B31: Departamento | E31: =_xlfn.XLOOKUP($C$23,'aux2'!$O:$O,'aux2'!$S:$S) | F31: =IFERROR(E31/E34,"") | G31: =(E31*C26)
B32: Estacionamiento | F32: =IFERROR(E32/E34,"") | G32: =(E32*C26)
B33: Bodega | F33: =IFERROR(E33/E34,"") | G33: =(E33*C26)
E34: =(E31+E32+E33) | G34: =(E34*C26)
B35: Descuento Venta | F35: 0.1
B36: Departamento | E36: =(E31*(100%-F35)) | F36: =IFERROR(E36/E39,"") | G36: =E36*C26
B37: Estacionamiento | E37: =E32 | F37: =IFERROR(E37/E39,"") | G37: =E37*C26
B38: Bodega | E38: =E33 | F38: =IFERROR(E38/E39,"") | G38: =E38*C26
B39: Total | E39: =SUM(E36:E38) | F39: =SUM(F36:F38) | G39: =E39*C26
B40: Pie Total | E40: =E39*F40 | F40: 0.1
B41: Reserva | E41: =G41/C26 | F41: =IFERROR(E41/E39,"") | G41: =_xlfn.XLOOKUP($C$23,'aux2'!$O:$O,'aux2'!$Y:$Y)
B42: Upfront a la Promesa | E42: =ROUND($E$39*$F$42,2) | F42: 0.02 | G42: =ROUND(E42*C26,0)
B43: Saldo Pie por Pagar | E43: =E40-E41-E42 | F43: =IFERROR(E43/E39,"") | G43: =E43*C26
B44: Credito Hipotecario | E44: =E39-E40 | F44: =IFERROR(E44/E39,"") | G44: =E44*C26
B45: Valor Compra
B47: Aporte Inmobiliaria | F47: 0.1
B48: Saldo Aporte Inmobiliaria | E48: =E51-E50-E49 | F48: =IFERROR(E48/E51,"") | G48: =E48*C26
B49: Credito Hipotecario | E49: =E51*F49 | F49: =100%-F40-F47 | G49: =E49*C26
B50: Pie pagado (Reserva+Upfront+Mutuo): | E50: =E41+E42+E43 | F50: =IFERROR(E50/E51,"") | G50: =E50*C26
B51: Valor de Venta (Tasacion) | E51: =E44/F49 | F51: =IFERROR(E51/E51,"") | G51: =E51*C26
B52: Plan de pago
E54: UF | F54: % | G54: $
B55: Valor | E55: =E39 | F55: 1 | G55: =E55*C26
B56: Upfront a la Promesa | E56: =E42 | F56: =IFERROR(E56/E39,"") | G56: =E56*C26
...

Sheet amort
A1: Crédito Hipotecario | B1: =ROUND(COTIZADOR!G60,0) | H1: Crédito Hipotecario | I1: =B1 | O1: Crédito Hipotecario | P1: =I1
A2: Plazo en años | B2: =COTIZADOR!E64 | H2: Plazo en años | I2: =COTIZADOR!F64 | O2: Plazo en años | P2: =COTIZADOR!G64
A3: CAE | B3: =COTIZADOR!E65 | H3: CAE | I3: =COTIZADOR!F65 | O3: CAE | P3: =COTIZADOR!G65
A4: CAE mensual | B4: =(1+B3)^(1/12)-1 | D4: pmt | H4: CAE mensual | I4: =(1+I3)^(1/12)-1 | O4: CAE mensual | P4: =(1+P3)^(1/12)-1
A5: pmt | B5: =ROUND(PMT(B3/12,B2*12,-B1),6) | D5: acum | E5: =MAX(F8:F67) | H5: pmt | I5: =ROUND(PMT(I3/12,I2*12,-I1),6) | K5: acum | L5: =MAX(M8:M67) | O5: pmt | P5: =ROUND(PMT(P3/12,P2*12,-P1),6) | R5: acum | S5: =MAX(T8:T67)
A7: ct | B7: amort | C7: int | D7: pmt | E7: saldo | F7: acum | H7: ct | I7: amort | J7: int | K7: pmt | L7: saldo | M7: acum | O7: ct | P7: amort | Q7: int | R7: pmt | S7: saldo | T7: acum
A8: 1 | B8: =ROUND(D8-C8,0) | C8: =ROUND(B1*$B$4,0) | D8: =$B$5 | E8: =ROUND(B1-B8,0) | F8: =B8 | H8: 1 | I8: =ROUND(K8-J8,0) | J8: =ROUND(I1*$B$4,0) | K8: =$I$5 | L8: =ROUND(I1-I8,0) | M8: =I8 | O8: 1 | P8: =ROUND(R8-Q8,0) | Q8: =ROUND(P1*$B$4,0) | R8: =$P$5 | S8: =ROUND(P1-P8,0) | T8: =P8
A9: 2 | B9: =ROUND(D9-C9,0) | C9: =ROUND(E8*$B$4,0) | D9: =$B$5 | E9: =ROUND(E8-B9,0) | F9: =ROUND(F8+B9,0) | H9: 2 | I9: =ROUND(K9-J9,0) | J9: =ROUND(L8*$B$4,0) | K9: =$B$5 | L9: =ROUND(L8-I9,0) | M9: =ROUND(M8+I9,0) | O9: 2 | P9: =ROUND(R9-Q9,0) | Q9: =ROUND(S8*$B$4,0) | R9: =$B$5 | S9: =ROUND(S8-P9,0) | T9: =ROUND(T8+P9,0)
A10: 3 | B10: =ROUND(D10-C10,0) | C10: =ROUND(E9*$B$4,0) | D10: =$B$5 | E10: =ROUND(E9-B10,0) | F10: =ROUND(F9+B10,0) | H10: 3 | I10: =ROUND(K10-J10,0) | J10: =ROUND(L9*$B$4,0) | K10: =$B$5 | L10: =ROUND(L9-I10,0) | M10: =ROUND(M9+I10,0) | O10: 3 | P10: =ROUND(R10-Q10,0) | Q10: =ROUND(S9*$B$4,0) | R10: =$B$5 | S10: =ROUND(S9-P10,0) | T10: =ROUND(T9+P10,0)
A11: 4 | B11: =ROUND(D11-C11,0) | C11: =ROUND(E10*$B$4,0) | D11: =$B$5 | E11: =ROUND(E10-B11,0) | F11: =ROUND(F10+B11,0) | H11: 4 | I11: =ROUND(K11-J11,0) | J11: =ROUND(L10*$B$4,0) | K11: =$B$5 | L11: =ROUND(L10-I11,0) | M11: =ROUND(M10+I11,0) | O11: 4 | P11: =ROUND(R11-Q11,0) | Q11: =ROUND(S10*$B$4,0) | R11: =$B$5 | S11: =ROUND(S10-P11,0) | T11: =ROUND(T10+P11,0)
A12: 5 | B12: =ROUND(D12-C12,0) | C12: =ROUND(E11*$B$4,0) | D12: =$B$5 | E12: =ROUND(E11-B12,0) | F12: =ROUND(F11+B12,0) | H12: 5 | I12: =ROUND(K12-J12,0) | J12: =ROUND(L11*$B$4,0) | K12: =$B$5 | L12: =ROUND(L11-I12,0) | M12: =ROUND(M11+I12,0) | O12: 5 | P12: =ROUND(R12-Q12,0) | Q12: =ROUND(S11*$B$4,0) | R12: =$B$5 | S12: =ROUND(S11-P12,0) | T12: =ROUND(T11+P12,0)
A13: 6 | B13: =ROUND(D13-C13,0) | C13: =ROUND(E12*$B$4,0) | D13: =$B$5 | E13: =ROUND(E12-B13,0) | F13: =ROUND(F12+B13,0) | H13: 6 | I13: =ROUND(K13-J13,0) | J13: =ROUND(L12*$B$4,0) | K13: =$B$5 | L13: =ROUND(L12-I13,0) | M13: =ROUND(M12+I13,0) | O13: 6 | P13: =ROUND(R13-Q13,0) | Q13: =ROUND(S12*$B$4,0) | R13: =$B$5 | S13: =ROUND(S12-P13,0) | T13: =ROUND(T12+P13,0)
A14: 7 | B14: =ROUND(D14-C14,0) | C14: =ROUND(E13*$B$4,0) | D14: =$B$5 | E14: =ROUND(E13-B14,0) | F14: =ROUND(F13+B14,0) | H14: 7 | I14: =ROUND(K14-J14,0) | J14: =ROUND(L13*$B$4,0) | K14: =$B$5 | L14: =ROUND(L13-I14,0) | M14: =ROUND(M13+I14,0) | O14: 7 | P14: =ROUND(R14-Q14,0) | Q14: =ROUND(S13*$B$4,0) | R14: =$B$5 | S14: =ROUND(S13-P14,0) | T14: =ROUND(T13+P14,0)
A15: 8 | B15: =ROUND(D15-C15,0) | C15: =ROUND(E14*$B$4,0) | D15: =$B$5 | E15: =ROUND(E14-B15,0) | F15: =ROUND(F14+B15,0) | H15: 8 | I15: =ROUND(K15-J15,0) | J15: =ROUND(L14*$B$4,0) | K15: =$B$5 | L15: =ROUND(L14-I15,0) | M15: =ROUND(M14+I15,0) | O15: 8 | P15: =ROUND(R15-Q15,0) | Q15: =ROUND(S14*$B$4,0) | R15: =$B$5 | S15: =ROUND(S14-P15,0) | T15: =ROUND(T14+P15,0)
A16: 9 | B16: =ROUND(D16-C16,0) | C16: =ROUND(E15*$B$4,0) | D16: =$B$5 | E16: =ROUND(E15-B16,0) | F16: =ROUND(F15+B16,0) | H16: 9 | I16: =ROUND(K16-J16,0) | J16: =ROUND(L15*$B$4,0) | K16: =$B$5 | L16: =ROUND(L15-I16,0) | M16: =ROUND(M15+I16,0) | O16: 9 | P16: =ROUND(R16-Q16,0) | Q16: =ROUND(S15*$B$4,0) | R16: =$B$5 | S16: =ROUND(S15-P16,0) | T16: =ROUND(T15+P16,0)
A17: 10 | B17: =ROUND(D17-C17,0) | C17: =ROUND(E16*$B$4,0) | D17: =$B$5 | E17: =ROUND(E16-B17,0) | F17: =ROUND(F16+B17,0) | H17: 10 | I17: =ROUND(K17-J17,0) | J17: =ROUND(L16*$B$4,0) | K17: =$B$5 | L17: =ROUND(L16-I17,0) | M17: =ROUND(M16+I17,0) | O17: 10 | P17: =ROUND(R17-Q17,0) | Q17: =ROUND(S16*$B$4,0) | R17: =$B$5 | S17: =ROUND(S16-P17,0) | T17: =ROUND(T16+P17,0)
A18: 11 | B18: =ROUND(D18-C18,0) | C18: =ROUND(E17*$B$4,0) | D18: =$B$5 | E18: =ROUND(E17-B18,0) | F18: =ROUND(F17+B18,0) | H18: 11 | I18: =ROUND(K18-J18,0) | J18: =ROUND(L17*$B$4,0) | K18: =$B$5 | L18: =ROUND(L17-I18,0) | M18: =ROUND(M17+I18,0) | O18: 11 | P18: =ROUND(R18-Q18,0) | Q18: =ROUND(S17*$B$4,0) | R18: =$B$5 | S18: =ROUND(S17-P18,0) | T18: =ROUND(T17+P18,0)
A19: 12 | B19: =ROUND(D19-C19,0) | C19: =ROUND(E18*$B$4,0) | D19: =$B$5 | E19: =ROUND(E18-B19,0) | F19: =ROUND(F18+B19,0) | H19: 12 | I19: =ROUND(K19-J19,0) | J19: =ROUND(L18*$B$4,0) | K19: =$B$5 | L19: =ROUND(L18-I19,0) | M19: =ROUND(M18+I19,0) | O19: 12 | P19: =ROUND(R19-Q19,0) | Q19: =ROUND(S18*$B$4,0) | R19: =$B$5 | S19: =ROUND(S18-P19,0) | T19: =ROUND(T18+P19,0)
A20: 13 | B20: =ROUND(D20-C20,0) | C20: =ROUND(E19*$B$4,0) | D20: =$B$5 | E20: =ROUND(E19-B20,0) | F20: =ROUND(F19+B20,0) | H20: 13 | I20: =ROUND(K20-J20,0) | J20: =ROUND(L19*$B$4,0) | K20: =$B$5 | L20: =ROUND(L19-I20,0) | M20: =ROUND(M19+I20,0) | O20: 13 | P20: =ROUND(R20-Q20,0) | Q20: =ROUND(S19*$B$4,0) | R20: =$B$5 | S20: =ROUND(S19-P20,0) | T20: =ROUND(T19+P20,0)
... A67: 60 | B67: =ROUND(D67-C67,0) | C67: =ROUND(E66*$B$4,0) | D67: =$B$5 | E67: =ROUND(E66-B67,0) | F67: =ROUND(F66+B67,0) | H67: 60 | I67: =ROUND(K67-J67,0) | J67: =ROUND(L66*$B$4,0) | K67: =$B$5 | L67: =ROUND(L66-I67,0) | M67: =ROUND(M66+I67,0) | O67: 60 | P67: =ROUND(R67-Q67,0) | Q67: =ROUND(S66*$B$4,0) | R67: =$B$5 | S67: =ROUND(S66-P67,0) | T67: =ROUND(T66+P67,0)

Sheet aux
A1: {=IFERROR(_xlfn.UNIQUE(_xlfn._xlws.FILTER('[1]STOCK NUEVOS'!A:A,'[1]STOCK NUEVOS'!C:C=COTIZADOR!$F$16)),"")} | B1: {=IFERROR(_xlfn._xlws.SORT(_xlfn.UNIQUE(_xlfn._xlws.FILTER('[1]STOCK NUEVOS'!B:B,('[1]STOCK NUEVOS'!A:A=COTIZADOR!$C$18)*('[1]STOCK NUEVOS'!C:C=COTIZADOR!$F$16))),1,TRUE),"")} | C1: 0.035 | D1: 0 | F1: 20 | I1: Antofagasta
A2: MAESTRA | B2: CÁCERES | C2: 0.04 | D2: 0.05 | F2: 25 | I2: Cerrillos
A3: RVC | B3: JARDINES DE ALVARADO | C3: 0.045 | D3: 0.1 | F3: 30 | I3: Concepción
A4: TOCTOC | B4: MIRADOR MAPOCHO | C4: 0.05 | D4: 0.15 | I4: Coquimbo
A5: URMENETA | B5: PINTOR CICARELLI I (PC I) | D5: 0.2 | I5: Estacion Central
B6: PINTOR CICARELLI II | D6: 0.25 | I6: Independencia
B7: PLAZA CERVANTES I | D7: 0.3 | I7: La Cisterna
B8: PLAZA CERVANTES II | D8: 0.35 | I8: La Florida
B9: PLAZA QUILICURA | D9: 0.4 | I9: Ñuñoa
B10: TRINIDAD III | I10: Providencia
B11: VISTA COSTANERA | I11: Puerto Montt
B12: VISTA RELONCAVÍ | I12: Quilicura
I13: Quinta Normal
I14: Rancagua
I15: Renca
I16: San Joaquín
I17: Santiago
I18: Temuco
I19: Valparaiso
I20: Viña del Mar

Sheet aux2
A1: ALIANZA | B1: =COTIZADOR!$C$18 | E1: ALIANZA | F1: NOMBRE PROYECTO | G1: TIPO ENTREGA | H1: PERIODO ENTREGA | I1: DIRECCION | J1: COMUNA | K1: ESTADO STOCK | L1: TIPO UNIDAD | M1: PROGRAMA | N1: PISO PRODUCTO | O1: NUMERO UNIDAD | P1: ORIENTACION | Q1: DORMITORIOS | R1: BAÑOS | S1: PRECIO LISTA | T1: SUPERFICIE TERRENO | U1: SUPERFICIE UTIL | V1: SUPERFICIE TERRAZA | W1: SUPERFICIE TOTAL | X1: BIENES CONJUNTOS | Y1: RESERVA | Z1: DESCUENTO | AA1: BONO PIE | AB1: CUOTAS PIE | AC1: PIE PERÍODO CONSTRUCCIÓN | AD1: CUOTÓN | AE1: PIE CRÉDITO DIRECTO
A2: NOMBRE PROYECTO | B2: =COTIZADOR!$F$18 | E2: {=_xlfn.LET(_xlpm.datos,'STOCK NUEVOS'!A2:U5000,_xlpm.enc,'STOCK NUEVOS'!A1:U1,_xlpm.r,_xlfn._xlws.FILTER(_xlpm.datos,(INDEX(_xlpm.datos,,_xlfn.XMATCH("ALIANZA",_xlpm.enc))='aux2'!$B$1)*(INDEX(_xlpm.datos,,_xlfn.XMATCH("NOMBRE PROYECTO",_xlpm.enc))='aux2'!$B$2)*(INDEX(_xlpm.datos,,_xlfn.XMATCH("TIPO ENTREGA",_xlpm.enc))='aux2'!$B$3)*(INDEX(_xlpm.datos,,_xlfn.XMATCH("TIPO UNIDAD",_xlpm.enc))='aux2'!$B$4)*(TRIM(INDEX(_xlpm.datos,,_xlfn.XMATCH("NUMERO UNIDAD",_xlpm.enc))&"")<>""),""),_xlpm.u,_xlfn.UNIQUE(_xlpm.r),_xlfn.SORTBY(_xlpm.u,_xlfn.CHOOSECOLS(_xlpm.u,_xlfn.XMATCH("NUMERO UNIDAD",_xlpm.enc)),1))} | F2: PLAZA CERVANTES I | G2: PLAZA CERVANTES I | H2: Entrega Inmediata | I2: Inmediata | J2: Chile España 8141 | K2: La Cisterna | L2: Disponible | M2: Departamento | N2: 2D1B | O2: 1 | P2: 113 | Q2: NORTE | R2: 2 | S2: 1 | T2: 2376 | V2: 36,9 | W2: 2,24 | X2: 39.14
A3: TIPO ENTREGA | B3: =COTIZADOR!$F$16 | E3: MAESTRA | F3: PLAZA CERVANTES I | G3: PLAZA CERVANTES I | H3: Entrega Inmediata | I3: Inmediata | J3: Chile España 8141 | K3: La Cisterna | L3: Arrendado | M3: Departamento | N3: 2D1B | O3: 4 | P3: 409 | Q3: SUR | R3: 2 | S3: 1 | T3: 2376 | V3: 36,9 | W3: 2,24 | X3: 39.14
A4: TIPO UNIDAD | B4: Departamento | E4: MAESTRA | F4: PLAZA CERVANTES I | G4: PLAZA CERVANTES I | H4: Entrega Inmediata | I4: Inmediata | J4: Chile España 8141 | K4: La Cisterna | L4: Arrendado | M4: Departamento | N4: 2D1B | O4: 4 | P4: 412 | Q4: NORTE | R4: 2 | S4: 1 | T4: 2456 | V4: 36,9 | W4: 2,24 | X4: 39.14
E5: MAESTRA | F5: PLAZA CERVANTES I | G5: PLAZA CERVANTES I | H5: Entrega Inmediata | I5: Inmediata | J5: Chile España 8141 | K5: La Cisterna | L5: Arrendado | M5: Departamento | N5: 2D1B | O5: 5 | P5: 513 | Q5: NORTE | R5: 2 | S5: 1 | T5: 2467 | V5: 36,9 | W5: 2,24 | X5: 39.14
E6: MAESTRA | F6: PLAZA CERVANTES I | G6: PLAZA CERVANTES I | H6: Entrega Inmediata | I6: Inmediata | J6: Chile España 8141 | K6: La Cisterna | L6: Arrendado | M6: Departamento | N6: 2D1B | O6: 6 | P6: 613 | Q6: NORTE | R6: 2 | S6: 1 | T6: 2479 | V6: 36,9 | W6: 2,24 | X6: 39.14
E7: MAESTRA | F7: PLAZA CERVANTES I | G7: PLAZA CERVANTES I | H7: Entrega Inmediata | I7: Inmediata | J7: Chile España 8141 | K7: La Cisterna | L7: Arrendado | M7: Departamento | N7: 2D1B | O7: 7 | P7: 709 | Q7: SUR | R7: 2 | S7: 1 | T7: 2410 | V7: 36,9 | W7: 2,24 | X7: 39.14
E8: MAESTRA | F8: PLAZA CERVANTES I | G8: PLAZA CERVANTES I | H8: Entrega Inmediata | I8: Inmediata | J8: Chile España 8141 | K8: La Cisterna | L8: Disponible | M8: Departamento | N8: 2D1B | O8: 8 | P8: 809 | Q8: SUR | R8: 2 | S8: 1 | T8: 2422 | V8: 36,9 | W8: 2,24 | X8: 39.14
E9: MAESTRA | F9: PLAZA CERVANTES I | G9: PLAZA CERVANTES I | H9: Entrega Inmediata | I9: Inmediata | J9: Chile España 8141 | K9: La Cisterna | L9: Arrendado | M9: Departamento | N9: 2D1B | O9: 9 | P9: 909 | Q9: SUR | R9: 2 | S9: 1 | T9: 2433 | V9: 36,9 | W9: 2,24 | X9: 39.14
E10: MAESTRA | F10: PLAZA CERVANTES I | G10: PLAZA CERVANTES I | H10: Entrega Inmediata | I10: Inmediata | J10: Chile España 8141 | K10: La Cisterna | L10: Disponible | M10: Departamento | N10: 2D1B | O10: 10 | P10: 1012 | Q10: NORTE | R10: 2 | S10: 1 | T10: 2525 | V10: 36,9 | W10: 2,24 | X10: 39.14

Sheet REGLAS_INMOBILIARIAS
A1: ALIANZA | B1: TIPO_CALCULO_BONO | C1: LTV_MAX_PCT | D1: PIE_CONJUNTOS_PCT | E1: DESCRIPCION_BONO_PIE
A2: MAESTRA | B2: maestra | C2: 0.8 | D2: 0.2 | E2: Bono sobre TASACION BANCO (fórmula D35/D36 Excel). Crédito hipotecario = tasación × LTV_MAX_PCT.
A3: INGEVEC | B3: precio-lista-depto | C3: 1 | D3: 0.2 | E3: Bono = Precio Lista DEPTO × %BonoPie. Tasación = Valor Venta + Bono. Crédito = Valor Venta - Pie - Aporte.
A4: RVC | B4: precio-lista-depto | C4: 1 | D4: 0.2 | E4: Bono = Precio Lista DEPTO × %BonoPie. Tasación = Valor Venta + Bono. Crédito = Valor Venta - Pie - Aporte.
A5: URMENETA | B5: precio-lista-total | C5: 1 | D5: 0.2 | E5: Bono = Precio Lista TOTAL (depto+estac+bodega) × %BonoPie. Tasación = Valor Venta + Bono. Crédito = Valor Venta - Pie - Aporte.
A6: TOCTOC | B6: precio-lista-depto | C6: 1 | D6: 0.2 | E6: Bono = Precio Lista DEPTO × %BonoPie. Tasación = Valor Venta + Bono. Crédito = Valor Venta - Pie - Aporte.
A7: EURO | B7: precio-lista-depto | C7: 1 | D7: 0.2 | E7: Bono = Precio Lista DEPTO × %BonoPie. Tasación = Valor Venta + Bono. Crédito = Valor Venta - Pie - Aporte.

Sheet PARAMETROS_CALCULO
A1: PARAMETRO | B1: VALOR | C1: TIPO | D1: DESCRIPCION
A2: MESES_ARRIENDO_ANIO | B2: 11 | C2: number | D2: Meses de arriendo por año asumidos (1 mes vacío). Usado en Cap Rate y flujo acumulado.
A3: HAIRCUT_VENTA | B3: 0.95 | C3: decimal | D3: Factor de castigo sobre valor de venta proyectado al año 5 (simula costos de transacción).
A4: PLUSVALIA_ANUAL_DEFAULT | B4: 0.02 | C4: decimal | D4: Plusvalía anual estimada por defecto (2%). Editable en UI.
A5: PIE_CONJUNTOS_PCT | B5: 0.2 | C5: decimal | D5: Porcentaje de pie obligatorio para bienes conjuntos (estacionamiento, bodega). Fijo, no editable.
A6: UPFRONT_PCT_DEFAULT | B6: 0.02 | C6: decimal | D6: Upfront a la Promesa por defecto (2%). Editable en UI. Aplica a todas las inmobiliarias.
A7: PIE_DEFAULT_PCT | B7: 0.1 | C7: decimal | D7: Porcentaje de pie por defecto para el departamento cuando no hay bono pie.
A8: PIE_CON_BONO_FORMULA | B8: 0.20 - BONO_PIE_PCT | C8: formula | D8: Fórmula para calcular pie default cuando hay bono pie: max(0, 0.20 - %BonoPie).
A9: PLAZO_DEFAULT_ANIOS | B9: 30 | C9: number | D9: Plazo hipotecario por defecto en años.
A10: CAE_DEFAULT_1 | B10: 0.04 | C10: decimal | D10: Tasa CAE por defecto escenario 1.
A11: CAE_DEFAULT_2 | B11: 0.045 | C11: decimal | D11: Tasa CAE por defecto escenario 2.
A12: CAE_DEFAULT_3 | B12: 0.05 | C12: decimal | D12: Tasa CAE por defecto escenario 3.
A13: FORMULA_CAP_RATE | B13: (arriendo_mensual * MESES_ARRIENDO_ANIO / valor_UF) / tasacion_UF | C13: formula | D13: Cap Rate anual: renta bruta anual en UF sobre tasación banco.
A14: FORMULA_ROI_5_ANIOS | B14: (precio_venta_anio5 - valor_venta + flujo_acumulado) / equity_base | C14: formula | D14: ROI sobre equity pagado (pie) en 5 años. Incluye plusvalía y flujo de arriendo neto.
A15: FORMULA_ROI_ANUAL | B15: (1 + ROI_5_ANIOS)^(1/5) - 1 | C15: formula | D15: ROI anual compuesto equivalente al ROI en 5 años.
A16: FORMULA_PRECIO_VENTA_5 | B16: valor_venta * (1 + plusvalia_anual)^5 * HAIRCUT_VENTA | C16: formula | D16: Precio de venta proyectado al año 5 con castigo por costos de transacción.
